Workbook

Sheet TC Count
B1: Module | C1: Type | D1: Type2 | E1: BGC | G1: CNG | I1: SCG | K1: CMP | M1: NYSEG | O1: RGE | Q1: UI
E2: iOS | F2: Android | G2: iOS | H2: Android | I2: iOS | J2: Android | K2: Android | L2: iOS | M2: Android | N2: iOS | O2: Android | P2: iOS | Q2: Android | R2: iOS
B3: Make a Payment Flow | C3: Regression | D3: Automated | E3: 91 | F3: 91 | G3: 87 | H3: 87 | I3: 87 | J3: 87 | K3: 227 | L3: 227 | M3: 52 | N3: 53 | O3: 53 | P3: 53 | Q3: 109 | R3: 111
B4: Manage Payment Method & Wallet | C4: Regression | D4: Automated | E4: 29 | F4: 29 | G4: 29 | H4: 29 | I4: 29 | J4: 29 | K4: 29 | L4: 29 | M4: 29 | N4: 29 | O4: 29 | P4: 29 | Q4: 29 | R4: 29
B5: Test Cases for Real Devices | C5: Regression | D5: Manual | E5: 42 | F5: 42 | G5: 42 | H5: 42 | I5: 43 | J5: 42 | K5: 42 | L5: 42 | M5: 42 | N5: 42 | O5: 42 | P5: 42 | Q5: 42 | R5: 42
B6: Log In | C6: QAT | D6: Automated | E6: 8 | F6: 8 | G6: 8 | H6: 8 | I6: 8 | J6: 9 | K6: 25 | L6: 25 | M6: 22 | N6: 17 | O6: 34 | P6: 17 | Q6: 24 | R6: 26
B7: Widget Status | C7: QAT | D7: Automated | E7: 8 | F7: 8 | G7: 8 | H7: 8 | I7: 8 | J7: 9 | K7: 7 | L7: 7 | M7: 7 | N7: 7 | O7: 7 | P7: 7 | Q7: 7 | R7: 7
B8: Dashboard | C8: QAT | D8: Automated | E8: 7 | F8: 7 | G8: 7 | H8: 7 | I8: 7 | J8: 7 | K8: 78 | L8: 78 | M8: 67 | N8: 67 | O8: 67 | P8: 67 | Q8: 67 | R8: 67 | T8: Billing&Payments | W8: My Preferences | AA8: My Accounts
B9: Bills & Payment | C9: QAT | D9: Automated | E9: 100 | F9: 100 | G9: 98 | H9: 98 | I9: 98 | J9: 98 | K9: 98 | L9: 98 | M9: 98 | N9: 98 | O9: 98 | P9: 98 | Q9: 96 | R9: 96 | T9: Make a Payment | W9: Push Notifications | AA9: Switch Accounts
B10: My Preferences | C10: QAT | D10: Automated | E10: 90 | F10: 92 | G10: 85 | H10: 85 | I10: 90 | J10: 90 | K10: 82 | L10: 82 | M10: 82 | N10: 82 | O10: 82 | P10: 82 | Q10: 82 | R10: 82 | T10: Enroll in e-Bill | W10: Alert Preferences | AA10: Make a Payment
B11: My Accounts | C11: QAT | D11: Automated | E11: 117 | F11: 117 | G11: 117 | H11: 117 | I11: 117 | J11: 117 | K11: 117 | L11: 117 | M11: 117 | N11: 117 | O11: 117 | P11: 117 | Q11: 117 | R11: 117 | T11: View Bill | W11: e-Bill enroll/de-enroll | AA11: My Preferences
B12: Outages | C12: QAT | D12: Automated | E12: 0 | F12: 0 | G12: 0 | H12: 0 | I12: 0 | J12: 0 | K12: 91 | L12: 91 | M12: 18 | N12: 18 | O12: 18 | P12: 18 | Q12: 52 | R12: 52 | T12: Download Bill | W12: Autopay enroll/de-enroll | AA12: My Profile
B13: Safety | C13: QAT | D13: Automated | E13: 37 | F13: 31 | G13: 31 | H13: 40 | I13: 31 | J13: 34 | K13: 0 | L13: 0 | M13: 31 | N13: 31 | O13: 31 | P13: 31 | Q13: 0 | R13: 0 | T13: Cancel Payment | W13: Budget billing enroll/de-enroll (no cmp) | AA13: Web Redirect
B14: Promo | C14: QAT | D14: Automated | E14: 9 | F14: 0 | G14: 9 | H14: 0 | I14: 9 | J14: 0 | K14: 25 | L14: 25 | M14: 7 | N14: 4 | O14: 4 | P14: 4 | Q14: 4 | R14: 4 | T14: View Bill/Payment History | W14: Operations ET enroll/de-enroll | AA14: Lookout
B15: Liferay Banner | C15: QAT | D15: Automated | E15: 17 | F15: 16 | G15: 10 | H15: 12 | I15: 14 | J15: 15 | K15: 10 | L15: 10 | M15: 10 | N15: 10 | O15: 10 | P15: 10 | Q15: 10 | R15: 10 | W15: Biometrics | AA15: Delete My Account
B16: Surveys | C16: QAT | D16: Automated | E16: 40 | F16: 35 | G16: 40 | H16: 40 | I16: 45 | J16: 37 | K16: 13 | L16: 13 | M16: 13 | N16: 13 | O16: 13 | P16: 13 | Q16: 13 | R16: 13 | W16: Cash only enroll
B17: End Meter Alerts | C17: QAT | D17: Manual | E17: 0 | F17: 0 | G17: 0 | H17: 0 | I17: 0 | J17: 0 | K17: 0 | L17: 0 | M17: 4 | N17: 4 | O17: 4 | P17: 4 | Q17: 0 | R17: 0
B18: Energy Manager | C18: QAT | D18: Manual | E18: 0 | F18: 0 | G18: 0 | H18: 0 | I18: 0 | J18: 0 | K18: 26 | L18: 26 | M18: 26 | N18: 26 | O18: 0 | P18: 0 | Q18: 26 | R18: 26
B19: Mandatory Update | C19: QAT | D19: Manual | E19: 4 | F19: 4 | G19: 4 | H19: 4 | I19: 4 | J19: 4 | K19: 4 | L19: 4 | M19: 4 | N19: 4 | O19: 4 | P19: 4 | Q19: 4 | R19: 4
B20: Non Mandatory Update | C20: QAT | D20: Manual | E20: 7 | F20: 7 | G20: 7 | H20: 7 | I20: 7 | J20: 7 | K20: 7 | L20: 7 | M20: 7 | N20: 7 | O20: 7 | P20: 7 | Q20: 7 | R20: 7
B21: Schedule Maintenance | C21: QAT | D21: Manual | E21: 3 | F21: 3 | G21: 4 | H21: 3 | I21: 3 | J21: 3 | K21: 3 | L21: 3 | M21: 3 | N21: 3 | O21: 3 | P21: 3 | Q21: 3 | R21: 3
E22: =SUM(E3:E21) -> 609 | F22: =SUM(F3:F21) -> 590 | G22: =SUM(G3:G21) -> 586 | H22: =SUM(H3:H21) -> 587 | I22: =SUM(I3:I21) -> 600 | J22: =SUM(J3:J21) -> 588 | K22: =SUM(K3:K21) -> 884 | L22: =SUM(L3:L21) -> 884 | ... R22: =SUM(R3:R21) -> 696 | T22: =SUM(E22:R22) -> 9216 | U22: << Total (Automated + Manual)
E24: =SUM(E3:E5) -> 162 | F24: =SUM(F3:F5) -> 162 | G24: =SUM(G3:G5) -> 158 | H24: =SUM(H3:H5) -> 158 | I24: =SUM(I3:I5) -> 159 | J24: =SUM(J3:J5) -> 158 | K24: =SUM(K3:K5) -> 298 | L24: =SUM(L3:L5) -> 298 | ... R24: =SUM(R3:R5) -> 182 | T24: =SUM(E24:R24) -> 2410 | U24: << Regression
E25: =SUM(E3:E16) -> 595 | F25: =SUM(F3:F16) -> 576 | G25: =SUM(G3:G16) -> 571 | H25: =SUM(H3:H16) -> 573 | I25: =SUM(I3:I16) -> 586 | J25: =SUM(J3:J16) -> 574 | K25: =SUM(K3:K16) -> 844 | L25: =SUM(L3:L16) -> 844 | ... R25: =SUM(R3:R16) -> 656 | T25: =SUM(E25:R25) -> 8847 | U25: << Automated (Reqgression + QAT)

Sheet Native Mobile Tests
A1: Key | B1: Name | C1: Assigned to | D1: Scripts | E1: Tests | F1: Status | G1: Comments | H1: Priority | I1: Feature | J1: OS | K1: OPCO | L1: Folder | M1: Coverage (Issues) | N1: Precondition | O1: Objective | P1: Test Script (Step-by-Step) - Step | Q1: Test Script (Step-by-Step) - Test Data | R1: Test Script (Step-by-Step) - Expected Result | S1: Column1
A2: MNDC-T1879 | B2: CNG - MNDC-39 - [IOS] - Login with wrong password | C2: Kevin | D2: Done | E2: Passed | F2: Complete | H2: =IF(I2="",200,VLOOKUP(I2,#REF!,2,FALSE)) -> #REF! | I2: Login | J2: IOS | K2: CNG | L2: /Login/CNG/IOS | M2: MNDC-39 | O2: Check if is validating the data informed in the login page fields | P2: I access login page *Then I should not be logged in and a message informing that the username or password is incorrect must be shown | R2: See the login fields and button *I should not be logged in, and I must see a validation message
A3: MNDC-T1877 | B3: CNG - MNDC-39 - [IOS] -Login with empty password field | C3: Kevin | D3: Done | E3: Passed | F3: Complete | H3: =IF(I3="",200,VLOOKUP(I3,#REF!,2,FALSE)) -> #REF! | I3: Login | J3: IOS | K3: CNG | L3: /Login/CNG/IOS | M3: MNDC-39 | O3: Check if is validating the data informed in the login page fields | P3: I access login page *Then the Log in button should be disabled | R3: See the login fields and button *The button should not be clickable if the mandatory information are not filled
A4: MNDC-T1878 | B4: CNG - MNDC-39 - [IOS] -Login with empty username field | C4: Kevin | D4: Done | E4: Passed | F4: Complete | H4: =IF(I4="",200,VLOOKUP(I4,#REF!,2,FALSE)) -> #REF! | I4: Login | J4: IOS | K4: CNG | L4: /Login/CNG/IOS | M4: MNDC-39 | O4: Check if is validating the data informed in the login page fields | P4: I access login page *Then the Log in button should be disabled | R4: See the login fields and button *The button should not be clickable if the mandatory information are not filled
A5: MNDC-T1961 | B5: CNG - MNDC-39 - [IOS] - Click on the tooltip in the username field in the login page to see tips about how to log in. | C5: Kevin | D5: Done | E5: Passed | F5: Complete | H5: =IF(I5="",200,VLOOKUP(I5,#REF!,2,FALSE)) -> #REF! | I5: Login | J5: IOS | K5: CNG | L5: /Login/CNG/IOS | O5: Check if is showing the message with the login instructions | P5: I access login page *Then I should see the instructions about the login | R5: See the login fields and buttons *The message should be as expected
A6: MNDC-T1881 | B6: CNG - MNDC-39 - [IOS] - Invalid/Incorrect username | C6: Kevin | D6: Done | E6: Passed | F6: Complete | H6: =IF(I6="",200,VLOOKUP(I6,#REF!,2,FALSE)) -> #REF! | I6: Login | J6: IOS | K6: CNG | L6: /Login/CNG/IOS | M6: MNDC-39 | O6: Check if the user is alowed to login correctly in the app | P6: I access login page *When I click on the Log in button Then I should not be logged in and a message informing that the username or password is incorrect must be shown | R6: See the login fields and button *The Log in button should be clickable
A7: MNDC-T1880 | B7: CNG - MNDC-39 - [IOS] - Successful login | C7: Kevin | D7: Done | E7: Passed | F7: Complete | H7: =IF(I7="",200,VLOOKUP(I7,#REF!,2,FALSE)) -> #REF! | I7: Login | J7: IOS | K7: CNG | L7: /Login/CNG/IOS | M7: MNDC-39 | O7: Check if is validating the data informed in the login page fields | P7: I access login page *Then I should be logged in and redirected to the Dashboard page | R7: See the login fields and button *I should be logged inand redirected to the dashboard page
A8: MNDC-T1883 | B8: CNG - MNDC-44 - [IOS] - Check splash screen display | C8: Kevin | D8: Done | E8: Passed | F8: Complete | H8: =IF(I8="",200,VLOOKUP(I8,#REF!,2,FALSE)) -> #REF! | I8: Login | J8: IOS | K8: CNG | L8: /Login/CNG/IOS | M8: MNDC-44 | O8: Validate if the logo is being correctly displayed | P8: When I access the app, then I should see the splash screen with the brand/OpCo logo | R8: The brand and the OpCo logo should be visible
A9: MNDC-T1882 | B9: MNDC-42 - CNG - [IOS] - Get message when offline | C9: Kevin | D9: Done | E9: Passed | F9: Complete | H9: =IF(I9="",200,VLOOKUP(I9,#REF!,2,FALSE)) -> #REF! | I9: Login | J9: IOS | K9: CNG | L9: /Login/CNG/IOS | M9: MNDC-42
A10: MNDC-T1932 | B10: CNG - MNDC-65 - [ANDROID] - Check splash screen display | C10: Jimmy | D10: Done | E10: Passed | F10: Done | H10: =IF(I10="",200,VLOOKUP(I10,#REF!,2,FALSE)) -> #REF! | I10: Login | J10: Android | K10: CNG | L10: /Login/CNG/ANDROID | M10: MNDC-65 | O10: Validate if the logo is being correctly displayed | P10: When I access the app, then I should see the splash screen with the brand/OpCo logo | R10: The brand and the OpCo logo should be visible
A11: MNDC-T1955 | B11: MNDC-62 - CNG - [ANDROID] - Click on the tooltip in the username field in the login page to see tips about how to log in. | C11: Jimmy | D11: Done | E11: Passed | F11: Done | H11: =IF(I11="",200,VLOOKUP(I11,#REF!,2,FALSE)) -> #REF! | I11: Login | J11: Android | K11: CNG | L11: /Login/CNG/ANDROID | O11: Check if is showing the message with the login instructions | P11: I access login page *Then I should see the instructions about the login | R11: See the login fields and buttons *The message should be as expected
A12: MNDC-T1928 | B12: MNDC-62 - CNG - [ANDROID] - Login with invalid username | C12: Jimmy | D12: Done | E12: Passed | F12: Done | H12: =IF(I12="",200,VLOOKUP(I12,#REF!,2,FALSE)) -> #REF! | I12: Login | J12: Android | K12: CNG | L12: /Login/CNG/ANDROID | M12: MNDC-62 | O12: Check if is validating the data informed in the login page fields | P12: Then the Log in button should be disabled *Then I should not be able to login | R12: The button should not be clickable if the mandatory information are not filled *The user should be allowed to login in app
A13: MNDC-T1927 | B13: MNDC-62 - CNG - [ANDROID] - Login with wrong password | C13: Jimmy | D13: Done | E13: Passed | F13: Done | H13: =IF(I13="",200,VLOOKUP(I13,#REF!,2,FALSE)) -> #REF! | I13: Login | J13: Android | K13: CNG | L13: /Login/CNG/ANDROID | M13: MNDC-62 | O13: Check if is validating the data informed in the login page fields | P13: I access login page *Then I should not be logged in and a message informing that the username or password is incorrect must be shown | R13: See the login fields and button *I should not be logged in, and I must see a validation message
A14: MNDC-T1929 | B14: MNDC-62 - CNG - [ANDROID] - Successful login | C14: Jimmy | D14: Done | E14: Passed | F14: Done | H14: =IF(I14="",200,VLOOKUP(I14,#REF!,2,FALSE)) -> #REF! | I14: Login | J14: Android | K14: CNG | L14: /Login/CNG/ANDROID | M14: MNDC-62 | O14: Check if the user is alowed to login correctly in the app | P14: I access login page *Then I should be able to login | R14: See the login fields and button *I should be able to login and land in home screen
A15: MNDC-T1925 | B15: MNDC-62 - CNG - [ANDROID] -Login with empty password field | C15: Jimmy | D15: Done | E15: Passed | F15: Done | H15: =IF(I15="",200,VLOOKUP(I15,#REF!,2,FALSE)) -> #REF! | I15: Login | J15: Android | K15: CNG | L15: /Login/CNG/ANDROID | M15: MNDC-62 | O15: Check if is validating the data informed in the login page fields | P15: I access login page *Then the Log in button should be disabled | R15: See the login fields and button *The button should not be clickable if the mandatory information are not filled
A16: MNDC-T1926 | B16: MNDC-62 - CNG - [ANDROID] -Login with empty username field | C16: Jimmy | D16: Done | E16: Passed | F16: Done | H16: =IF(I16="",200,VLOOKUP(I16,#REF!,2,FALSE)) -> #REF! | I16: Login | J16: Android | K16: CNG | L16: /Login/CNG/ANDROID | M16: MNDC-62 | O16: Check if is validating the data informed in the login page fields | P16: I access login page *Then the Log in button should be disabled | R16: See the login fields and button *The button should not be clickable if the mandatory information are not filled
A17: MNDC-T1931 | B17: MNDC-63 - CNG - [ANDROID] - Get message when offline | C17: Jimmy | D17: Done | E17: Passed | F17: Done | H17: =IF(I17="",200,VLOOKUP(I17,#REF!,2,FALSE)) -> #REF! | I17: Login | J17: Android | K17: CNG | L17: /Login/CNG/ANDROID | M17: MNDC-63 | O17: Checking the offline message validation | P17: When I try to navigate through the app I should see an offline message | R17: The system should show a message to the user informing that the dispositive is offline
A18: MNDC-T6801 | B18: CNG - IOS - MNDC-451 - Validate that the confirmation cancels when clicking on Go Back. | C18: Jimmy | D18: Done | E18: Passed | F18: Complete | H18: =IF(I18="",200,VLOOKUP(I18,#REF!,2,FALSE)) -> #REF! | I18: Manage Payment & Wallet | J18: IOS | K18: CNG | O18: Validate that the confirmation cancels when clicking on Go Back. | P18: Select an account with the "Payment Processing" status - or submit a payment in an account yourself. *Check that it should be back to the previuous screen ("Make a Payment").
A19: MNDC-T6800 | B19: CNG - IOS - MNDC-451 - Validate that the confirmation screen shows up. | C19: Jimmy | D19: Done | E19: Passed | F19: Complete | H19: =IF(I19="",200,VLOOKUP(I19,#REF!,2,FALSE)) -> #REF! | I19: Manage Payment & Wallet | J19: IOS | K19: CNG | O19: Validate that the confirmation screen shows up. | P19: Select an account with the "Payment Processing" status - or submit a payment in an account yourself. *Validate that the confirmation popup appear as it should.
A20: MNDC-T6803 | B20: CNG - IOS - MNDC-451 - Validate that the confirmation shows again when returning to the screen. | C20: Jimmy | D20: Done | E20: Passed | F20: Complete | H20: =IF(I20="",200,VLOOKUP(I20,#REF!,2,FALSE)) -> #REF! | I20: Manage Payment & Wallet | J20: IOS | K20: CNG | O20: Validate that the confirmation shows again when returning to the screen. | P20: Select an account with the "Payment Processing" status - or submit a payment in an account yourself. *Try to include the payment again and verify that the popup is shown again.
A21: MNDC-T6802 | B21: CNG - IOS - MNDC-451 - Validate that the payment goes through when continuing on the confirmation screen. | C21: Jimmy | D21: Done | E21: Passed | F21: Complete | H21: =IF(I21="",200,VLOOKUP(I21,#REF!,2,FALSE)) -> #REF! | I21: Manage Payment & Wallet | J21: IOS | K21: CNG | O21: Validate that the payment goes through when continuing on the confirmation screen. | P21: Select an account with the "Payment Processing" status - or submit a payment in an account yourself. *Check the Payments tab to verify that the additional payment was inserted.
A22: MNDC-T6804 | B22: CNG - IOS - MNDC-451 - Validate the confirmation popup's text. | C22: Jimmy | D22: Done | E22: Passed | F22: Complete | H22: =IF(I22="",200,VLOOKUP(I22,#REF!,2,FALSE)) -> #REF! | I22: Manage Payment & Wallet | J22: IOS | K22: CNG | O22: Validate the confirmation popup's text. | P22: Select an account with the "Payment Processing" status - or submit a payment in an account yourself. *Check that the text shown in the confirmation popup is the same as in the Story.
A23: MNDC-T6806 | B23: CNG - IOS - MNDC-451 - Validate the confirmation sceen on status other than Payment Processing | C23: Jimmy | D23: Done | E23: Passed | F23: Complete | H23: =IF(I23="",200,VLOOKUP(I23,#REF!,2,FALSE)) -> #REF! | I23: Manage Payment & Wallet | J23: IOS | K23: CNG | O23: Validate the confirmation sceen on status other than Payment Processing | P23: Select an account with a status other than "Payment Processing", such as Payment Past Due. *Check that the popup should NOT be shown and the payment shall go through, since the popup is for only additional payment.
A24: MNDC-T6805 | B24: CNG - IOS - MNDC-451 - Validation of the confirmation messages switching on and off the Remote Config. | C24: Jimmy | D24: Done | E24: Passed | F24: Complete | H24: =IF(I24="",200,VLOOKUP(I24,#REF!,2,FALSE)) -> #REF! | I24: Manage Payment & Wallet | J24: IOS | K24: CNG | O24: Validation of the confirmation messages switching on and off the Remote Config. | P24: Disable the warning popup in Remote config. *Try again and check that it should appear now.
A25: MNDC-T5960 | B25: CNG - MNDC-132 - Android - Kubra Add Failure Shows Error And No Add | C25: Jimmy | D25: Done | E25: Blocked | F25: Blocked | H25: =IF(I25="",200,VLOOKUP(I25,#REF!,2,FALSE)) -> #REF! | I25: Manage Payment & Wallet | J25: Android | K25: CNG | L25: /Manage Payment Method & Wallet/CNG/Android | N25: Kubra mock configured to return an error (e.g., 400/500) on add attempt. User on Kubra add flow. | O25: Verify the app handles a Kubra add-payment-method failure gracefully (error from Kubra) and does not add method to Payment methods list. | P25: 1. Open Payment Screen. *3. Observe Kubra/app behavior on failure and return to Payment methods screen (if user taps Back). | R25: 1. Kubra (or app) displays error message describing the failure. *3. After returning to Payment methods, the list remains unchanged.
A26: MNDC-T5958 | B26: CNG - MNDC-132 - Android - Open Kubra From AddBankAccount Button | C26: Jimmy | D26: Done | E26: Passed | F26: Done | H26: =IF(I26="",200,VLOOKUP(I26,#REF!,2,FALSE)) -> #REF! | I26: Manage Payment & Wallet | J26: Android | K26: CNG | L26: /Manage Payment Method & Wallet/CNG/Android | N26: User logged in on Payment methods screen. Firebase Remote Config "Add bank account" enabled. Network available. | O26: Verify that tapping the "Add bank account" button opens the Kubra screen. | P26: 1. Tap "Add bank account". *Add Credit/Debit card Payment method and complete the process | R26: App opens Kubra screen and shows loading state. *Credit/Debit card payment method is added successfully and seen in Payment method screen with Credit card icon
A27: MNDC-T5959 | B27: CNG - MNDC-132 - Android - Open Kubra From AddCard Button | C27: Jimmy | D27: Done | E27: Blocked | F27: Blocked | H27: =IF(I27="",200,VLOOKUP(I27,#REF!,2,FALSE)) -> #REF! | I27: Manage Payment & Wallet | J27: Android | K27: CNG | L27: /Manage Payment Method & Wallet/CNG/Android | N27: User logged in on Payment methods screen. Firebase Remote Config "Add credit and debit credit card" enabled. Network available. | O27: Verify that tapping the "Add credit and debit credit card" button opens the Kubra screen. | P27: 1. Tap "Add credit and debit credit card". *fill all required information and add the cc
A28: MNDC-T5957 | B28: CNG - MNDC-132 - Android - Open Kubra From ManageMyWallet Button | C28: Jimmy | D28: Done | E28: Passed | F28: Done | H28: =IF(I28="",200,VLOOKUP(I28,#REF!,2,FALSE)) -> #REF! | I28: Manage Payment & Wallet | J28: Android | K28: CNG | L28: /Manage Payment Method & Wallet/CNG/Android | N28: User is logged in and on Payment methods screen. Firebase Remote Config flag for "Manage my wallet" is enabled. Network available. Kubra external API reachable (or mock available). | O28: Verify that tapping the "Manage my wallet" button from the Payment methods screen opens the Kubra screen. | P28: 1. Tap "Manage my wallet". | R28: 1. App initiates navigation to Kubra (webview or external screen) and shows Kubra loading UI.
A29: MNDC-T7550 | B29: CNG - MNDC-1583 - Android - Checking CC's availability and display icon on adding a payment method. | H29: =IF(I29="",200,VLOOKUP(I29,#REF!,2,FALSE)) -> #REF! | I29: Manage Payment & Wallet | J29: Android | K29: CNG | L29: /Manage Payment Method & Wallet/CNG/Android | M29: MNDC-1583 | O29: Checking CC's availability and display icon on adding a payment method. | P29: From the Dashboard, advance to make a new payment; *Also check that, at the end of the CC/DC icon and name, the last four digits are shown as well and are consistente with the ones inserted before.
A30: MNDC-T7552 | B30: CNG - MNDC-1583 - Android - Checking CC's availability and display icon on changing payment methods. | H30: =IF(I30="",200,VLOOKUP(I30,#REF!,2,FALSE)) -> #REF! | I30: Manage Payment & Wallet | J30: Android | K30: CNG | L30: /Manage Payment Method & Wallet/CNG/Android | M30: MNDC-1583 | O30: Checking CC's availability and display icon on changing payment methods. | P30: From the Dashboard, advance to make a new payment; *Also check that, at the end of the CC/DC icon and name, the last four digits are shown as well.
A31: MNDC-T7551 | B31: CNG - MNDC-1583 - Android - Checking CC's availability and display icon on managing the wallet. | H31: =IF(I31="",200,VLOOKUP(I31,#REF!,2,FALSE)) -> #REF! | I31: Manage Payment & Wallet | J31: Android | K31: CNG | L31: /Manage Payment Method & Wallet/CNG/Android | M31: MNDC-1583 | O31: Checking CC's availability and display icon on managing the wallet. | P31: From the Dashboard, advance to make a new payment; *Also check that, at the end of the CC/DC icon and name, the last four digits are shown as well.
A32: MNDC-T7559 | B32: CNG - MNDC-1583 - iOS - Checking CC's availability and display icon on adding a payment method. | C32: Jimmy | D32: In Progress | F32: In Progress | H32: =IF(I32="",200,VLOOKUP(I32,#REF!,2,FALSE)) -> #REF! | I32: Manage Payment & Wallet | J32: IOS | K32: CNG | L32: /Manage Payment Method & Wallet/CNG/IOS | M32: MNDC-1583 | O32: Checking CC's availability and display icon on adding a payment method. | P32: From the Dashboard, advance to make a new payment; *Also check that, at the end of the CC/DC icon and name, the last four digits are shown as well and are consistente with the ones inserted before.
A33: MNDC-T7561 | B33: CNG - MNDC-1583 - iOS - Checking CC's availability and display icon on changing payment methods. | C33: Jimmy | D33: In Progress | F33: In Progress | H33: =IF(I33="",200,VLOOKUP(I33,#REF!,2,FALSE)) -> #REF! | I33: Manage Payment & Wallet | J33: IOS | K33: CNG | L33: /Manage Payment Method & Wallet/CNG/IOS | M33: MNDC-1583 | O33: Checking CC's availability and display icon on changing payment methods. | P33: From the Dashboard, advance to make a new payment; *Also check that, at the end of the CC/DC icon and name, the last four digits are shown as well.
A34: MNDC-T7560 | B34: CNG - MNDC-1583 - iOS - Checking CC's availability and display icon on managing the wallet. | C34: Jimmy | D34: In Progress | F34: In Progress | H34: =IF(I34="",200,VLOOKUP(I34,#REF!,2,FALSE)) -> #REF! | I34: Manage Payment & Wallet | J34: IOS | K34: CNG | L34: /Manage Payment Method & Wallet/CNG/IOS | M34: MNDC-1583 | O34: Checking CC's availability and display icon on managing the wallet. | P34: From the Dashboard, advance to make a new payment; *Also check that, at the end of the CC/DC icon and name, the last four digits are shown as well.
A35: MNDC-T5953 | B35: CNG - MNDC-258 - Android - API Error Handling | H35: =IF(I35="",200,VLOOKUP(I35,#REF!,2,FALSE)) -> #REF! | I35: Manage Payment & Wallet | J35: Android | K35: CNG | L35: /Manage Payment Method & Wallet/CNG/Android | N35: Ability to simulate API error or offline mode. | O35: Verify graceful handling of Payment Method API failures or network errors. | P35: 1. Trigger API failure scenario. *2. Open Manage payment method. | R35: 1. App receives API error or times out. *2. Screen shows an error message and a retry option or guidance; app does not crash.
A36: MNDC-T5954 | B36: CNG - MNDC-258 - Android - Default Payment Method Preselected Green Radio | C36: Jimmy | D36: Done | E36: Passed | F36: Done | H36: =IF(I36="",200,VLOOKUP(I36,#REF!,2,FALSE)) -> #REF! | I36: Manage Payment & Wallet | J36: Android | K36: CNG | L36: /Manage Payment Method & Wallet/CNG/Android | N36: Backend indicates a default method in API response. | O36: Verify the default payment method returned by API is preselected and shows a green radio. | P36: 1. Open Manage payment method. *Move around from one tab or screen to another and validate the above selected payment method is shown on both screens | R36: 1. Screen displays items. *User selected payment methods are shown until a new payment method is saved and selected on both Make a payment and Payment method screens
A37: MNDC-T5951 | B37: CNG - MNDC-258 - Android - Display Payment Methods List Populated From API | C37: Jimmy | D37: Done | E37: Passed | F37: Done | H37: =IF(I37="",200,VLOOKUP(I37,#REF!,2,FALSE)) -> #REF! | I37: Manage Payment & Wallet | J37: Android | K37: CNG | L37: /Manage Payment Method & Wallet/CNG/Android | N37: User logged in; network available; test account has N stored payment methods (N >= 1); API returns a valid list. | O37: Verify the "Manage payment method" screen displays the payment methods returned by the Payment Method API. | P37: 1. Open Manage payment method screen. *3. Inspect displayed list rows. | R37: 1. App issues Payment Method API request. *3. Screen shows one row per returned method with required labels/masked details and a radio control per row.
A38: MNDC-T5955 | B38: CNG - MNDC-258 - Android - Save Payment Method Redirect With Loader and New Selection | C38: Jimmy | D38: Done | E38: Passed | F38: Done | H38: =IF(I38="",200,VLOOKUP(I38,#REF!,2,FALSE)) -> #REF! | I38: Manage Payment & Wallet | J38: Android | K38: CNG | L38: /Manage Payment Method & Wallet/CNG/Android | N38: Save button visible (remote config ON); network available; backend saves default. | O38: Verify tapping "Save payment method" triggers loader, persists the new selection, and redirects to Make a Payment with that method preselected. | P38: 1. Tap Save payment method. *3. Observe redirection to Make a Payment. | R38: 1. Save flow starts and app calls backend (if applicable). *3. After success, app redirects to Make a Payment and the newly saved method is preselected.
A39: MNDC-T5956 | B39: CNG - MNDC-258 - Android - Save Without Change no Redirect With Loader | H39: =IF(I39="",200,VLOOKUP(I39,#REF!,2,FALSE)) -> #REF! | I39: Manage Payment & Wallet | J39: Android | K39: CNG | L39: /Manage Payment Method & Wallet/CNG/Android | N39: Save button visible and enabled. | O39: Verify tapping Save without changing selection still shows loader and redirects with the same method selected. | P39: 1. Tap Save payment method without altering selection. | R39: App redirects to Make a Payment with the same previously selected method.
A40: MNDC-T5952 | B40: CNG - MNDC-258 - Android - Supports payment methods added and are Scrollable | C40: Jimmy | D40: Done | E40: Passed | F40: Done | H40: =IF(I40="",200,VLOOKUP(I40,#REF!,2,FALSE)) -> #REF! | I40: Manage Payment & Wallet | J40: Android | K40: CNG | L40: /Manage Payment Method & Wallet/CNG/Android | N40: Test account prepopulated with added methods; device viewport smaller than list height. | O40: Verify the list supports all the payment methods added and is scrollable so all items can be viewed. | P40: 1. Open Manage payment method. *Validate the icons displayed for ACH and Credit/.Debit card payment methods | R40: 1. List initially shows the top portion of items. *For ACH account and Credit card separate icons are visible
...

Sheet Data
A1: Assigned to | B1: Scripts | C1: Tests | D1: Status
A2: Jimmy | B2: In Progress | C2: In Progress | D2: In Progress
A3: Kevin | B3: Failed | C3: Failed | D3: For Future
A4: Erick | B4: Blocked | C4: Blocked | D4: For Manual
A5: Surekha | B5: Done | C5: Passed | D5: Limited Resources
B6: No Auto | C6: No Auto | D6: Unstable
D7: Blocked
D8: Complete
D9: No Auto

Sheet MASTER PLAN_OLD
C1: March | Z1: April | BD1: May | CI1: June | DM1: July
C2: M | D2: T | E2: W | F2: Th | G2: F | H2: SA | I2: SU | J2: M | K2: T | L2: W | M2: Th | N2: F | O2: SA | P2: SU | Q2: M | R2: T | S2: W | T2: Th | U2: F | V2: SA | W2: SU | X2: M | Y2: T | Z2: W | AA2: Th | AB2: F | AC2: SA | AD2: SU | AE2: M | AF2: T | AG2: W | AH2: Th | AI2: F | AJ2: SA | AK2: SU | AL2: M | AM2: T | AN2: W | AO2: Th | AP2: F | AQ2: SA | AR2: SU | AS2: M | AT2: T | AU2: W | AV2: Th | AW2: F | AX2: SA | AY2: SU | AZ2: M | BA2: T | BB2: W | BC2: Th | BD2: F | BE2: SA | BF2: SU | BG2: M | BH2: T | BI2: W | BJ2: Th | BK2: F | BL2: SA | BM2: SU | BN2: M | BO2: T | BP2: W | BQ2: Th | BR2: F | BS2: SA | BT2: SU | BU2: M | BV2: T | BW2: W | BX2: Th | BY2: F | BZ2: SA | CA2: SU | CB2: M | CC2: T | CD2: W | CE2: Th | CF2: F | CG2: SA | CH2: SU | CI2: M | CJ2: T | CK2: W | CL2: Th | CM2: F | CN2: SA | CO2: SU | CP2: M | CQ2: T | CR2: W | CS2: Th | CT2: F | CU2: SA | CV2: SU | CW2: M | CX2: T | CY2: W | CZ2: Th | DA2: F | DB2: SA | DC2: SU | DD2: M | DE2: T | DF2: W | DG2: Th | DH2: F | DI2: SA | DJ2: SU | DK2: M | DL2: T | DM2: W | DN2: Th | DO2: F | DP2: SA | DQ2: SU | DR2: M | DS2: T | DT2: W | DU2: Th | DV2: F | DW2: SA | DX2: SU
C3: 9 | D3: 10 | E3: 11 | F3: 12 | G3: 13 | H3: 14 | I3: 15 | J3: 16 | K3: 17 | L3: 18 | M3: 19 | N3: 20 | O3: 21 | P3: 22 | Q3: 23 | R3: 24 | S3: 25 | T3: 26 | U3: 27 | V3: 28 | W3: 29 | X3: 30 | Y3: 31 | Z3: 1 | AA3: 2 | AB3: 3 | AC3: 4 | AD3: 5 | AE3: 6 | AF3: 7 | AG3: 8 | AH3: 9 | AI3: 10 | AJ3: 11 | AK3: 12 | AL3: 13 | AM3: 14 | AN3: 15 | AO3: 16 | AP3: 17 | AQ3: 18 | AR3: 19 | AS3: 20 | AT3: 21 | AU3: 22 | AV3: 23 | AW3: 24 | AX3: 25 | AY3: 26 | AZ3: 27 | BA3: 28 | BB3: 29 | BC3: 30 | BD3: 1 | BE3: 2 | BF3: 3 | BG3: 4 | BH3: 5 | BI3: 6 | BJ3: 7 | BK3: 8 | BL3: 9 | BM3: 10 | BN3: 11 | BO3: 12 | BP3: 13 | BQ3: 14 | BR3: 15 | BS3: 16 | BT3: 17 | BU3: 18 | BV3: 19 | BW3: 20 | BX3: 21 | BY3: 22 | BZ3: 23 | CA3: 24 | CB3: 25 | CC3: 26 | CD3: 27 | CE3: 28 | CF3: 29 | CG3: 30 | CH3: 31 | CI3: 1 | CJ3: 2 | CK3: 3 | CL3: 4 | CM3: 5 | CN3: 6 | CO3: 7 | CP3: 8 | CQ3: 9 | CR3: 10 | CS3: 11 | CT3: 12 | CU3: 13 | CV3: 14 | CW3: 15 | CX3: 16 | CY3: 17 | CZ3: 18 | DA3: 19 | DB3: 20 | DC3: 21 | DD3: 22 | DE3: 23 | DF3: 24 | DG3: 25 | DH3: 26 | DI3: 27 | DJ3: 28 | DK3: 29 | DL3: 30 | DM3: 1 | DN3: 2 | DO3: 3 | DP3: 4 | DQ3: 5 | DR3: 6 | DS3: 7 | DT3: 8 | DU3: 9 | DV3: 10 | DW3: 11 | DX3: 12
B4: BGC - iOS / Android
B5: CMP - iOS / Android | L5: QAT | Z5: Regression
B6: NYSEG - iOS / Android | AN6: QAT | BB6: Regression
B7: RG&E - iOS / Android | BP7: QAT | CD7: Regression
B8: UI - iOS / Android | CR8: QAT | DF8: Regression
A9: Automation Cycles | B9: Status
A10: Regression | B10: In Progress
A11: Manage Payment & Wallet | B11: In Progress
A12: CNG - iOS | B12: QA Validation
A13: CNG - Android | B13: QA Validation
A14: SCG - iOS | B14: Backlog
A15: SCG - Android | B15: Backlog
A16: BCG - iOS | B16: Backlog
A17: BCG - Android | B17: Backlog
A18: CMP - iOS | B18: Backlog
A19: CMP - Android | B19: Backlog
A20: NYSEG - iOS | B20: Backlog
... A206: UI - Android | B206: Backlog

Sheet MASTER PLAN
C1: Past | D1: 46090 | E1: =D1+7 -> 46097 | F1: =E1+7 -> 46104 | G1: =F1+7 -> 46111 | H1: =G1+7 -> 46118 | I1: =H1+7 -> 46125 | J1: =I1+7 -> 46132 | K1: =J1+7 -> 46139 | L1: =K1+7 -> 46146 | ... U1: =T1+7 -> 46209
A2: BGC - iOS / Android | B2: BGC - iOS / Android | X2: Release
A3: CMP - iOS / Android | B3: CMP - iOS / Android | X3: QAT
A4: NYSEG - iOS / Android | B4: NYSEG - iOS / Android | X4: Regression
A5: RG&E - iOS / Android | B5: RG&E - iOS / Android | X5: Mobile Automation
A6: UI - iOS / Android | B6: UI - iOS / Android | X6: Regression Milestone (target for OPCO mobile completion)
A7: Automation Cycles | B7: Status
A8: Regression | B8: In Progress
A9: Manage Payment & Wallet | B9: In Progress
A10: CNG - iOS/Android | B10: QA Validation
A11: SCG - iOS/Android | B11: Backlog
A12: BCG - iOS/Android | B12: Backlog
A13: CMP - iOS/Android | B13: Backlog
A14: NYSEG - iOS/Android | B14: Backlog
A15: RGE - iOS/Android | B15: Backlog
A16: UI - iOS/Android | B16: Backlog
A17: Make a Payment Flow | B17: In Progress
A18: CNG - iOS/Android | B18: In Progress
... A113: UI - iOS/Android | B113: Backlog

Sheet MASTER PLAN (4)
C1: Past | D1: 46090 | E1: =D1+7 -> 46097 | F1: =E1+7 -> 46104 | G1: =F1+7 -> 46111 | H1: =G1+7 -> 46118 | I1: =H1+7 -> 46125 | J1: =I1+7 -> 46132 | K1: =J1+7 -> 46139 | L1: =K1+7 -> 46146 | ... U1: =T1+7 -> 46209
A2: BGC - iOS / Android | B2: BGC - iOS / Android
A3: CMP - iOS / Android | B3: CMP - iOS / Android
A4: NYSEG - iOS / Android | B4: NYSEG - iOS / Android
A5: RG&E - iOS / Android | B5: RG&E - iOS / Android
A6: UI - iOS / Android | B6: UI - iOS / Android
A7: Automation Cycles | B7: Status
A8: CNG - iOS/Android | B8: In Progress
A9: Manage Payment & Wallet | B9: QA Validation
A10: Make a Payment Flow | B10: Backlog
A11: Log In | B11: Backlog
A12: Widget | B12: Backlog
A13: Bills & Payment | B13: Backlog
A14: My Preferences | B14: Backlog
A15: Dahsboard
A16: My Accounts
A17: Outages
A18: Safety
A19: Promo
A20: Liferay
A21: Surveys
A22: SCG - iOS/Android | B22: In Progress
A23: Manage Payment & Wallet | B23: QA Validation
A24: Make a Payment Flow | B24: Backlog
A25: Log In | B25: Backlog
A26: Widget | B26: Backlog
A27: Bills & Payment | B27: Backlog
A28: My Preferences | B28: Backlog
A29: Dahsboard
A30: My Accounts
A31: Outages
A32: Safety
A33: Promo
A34: Liferay
A35: Surveys
A36: BCG - iOS/Android | B36: Backlog
A37: Manage Payment & Wallet | B37: QA Validation
A38: Make a Payment Flow | B38: Backlog
A39: Log In | B39: Backlog
A40: Widget | B40: Backlog
...

Sheet Regression View
B1: Past | C1: 46090 | D1: =C1+7 -> 46097 | E1: =D1+7 -> 46104 | F1: =E1+7 -> 46111 | G1: =F1+7 -> 46118 | H1: =G1+7 -> 46125 | I1: =H1+7 -> 46132 | J1: =I1+7 -> 46139 | K1: =J1+7 -> 46146 | ... T1: =S1+7 -> 46209
A2: BGC - iOS / Android | W2: Release
A3: CMP - iOS / Android | W3: QAT
A4: NYSEG - iOS / Android | W4: Regression
A5: RG&E - iOS / Android | W5: Mobile Automation
A6: UI - iOS / Android | W6: Regression Milestone (target for OPCO mobile completion)
A7: Automation Cycles
A8: Regression
A9: Manage Payment & Wallet
A10: CNG - iOS/Android
A11: SCG - iOS/Android
A12: BCG - iOS/Android
A13: CMP - iOS/Android
A14: NYSEG - iOS/Android
A15: RGE - iOS/Android
A16: UI - iOS/Android
A17: Make a Payment Flow
A18: CNG - iOS/Android
... A24: UI - iOS/Android

Sheet Exec View
H2: Status
B3: OPCO | C3: Module | D3: Platform | E3: Total TC | F3: No Auto | G3: Automated TCs | H3: Pending | I3: In Progress | J3: QA Validation | K3: Auto
B4: CMP | C4: Manage Payments & Methods | D4: Android | E4: =COUNTA(ManagePayments!B7:B30) -> 24 | F4: =COUNTIF(ManagePayments!D7:D30,"No Auto") -> 7 | G4: =COUNTIFS(ManagePayments!D7:D30,"<>No Auto",ManagePayments!D7:D30,"<>") -> 17 | H4: =COUNTIF(ManagePayments!$D$7:$D$30,"=In Progress") -> 0 | I4: =COUNTIF(ManagePayments!$D$7:$D$30,"=In Progress") -> 0 | J4: =COUNTIF(ManagePayments!$D$7:$D$30,"=QA Validation") -> 17
D5: iOS | E5: =COUNTA(ManagePayments!B32:B55) -> 24 | F5: =COUNTIF(ManagePayments!D32:D55,"No Auto") -> 4 | G5: =COUNTIFS(ManagePayments!D32:D55,"<>No Auto",ManagePayments!D32:D55,"<>") -> 20 | H5: =COUNTIF(ManagePayments!$D$32:$D$55,"=In Progress") -> 0 | I5: =COUNTIF(ManagePayments!$D$32:$D$55,"=In Progress") -> 0 | J5: =COUNTIF(ManagePayments!$D$32:$D$55,"=QA Validation") -> 20
C6: Make a Payment Flow | D6: Android | E6: =COUNTA(MakePayment!B7:B57) -> 51 | F6: =COUNTIF(MakePayment!D7:D57,"No Auto") -> 4 | G6: =COUNTIFS(MakePayment!D7:D57,"<>No Auto",MakePayment!D7:D57,"<>") -> 0 | H6: 47 | I6: =COUNTIF(MakePayment!$D$7:$D$57,"=In Progress") -> 0 | J6: =COUNTIF(MakePayment!$D$7:$D$57,"=QA Validation") -> 0
D7: iOS | E7: =COUNTA(MakePayment!B59:B109) -> 51 | F7: =COUNTIF(MakePayment!D59:D109,"No Auto") -> 21 | G7: =COUNTIFS(MakePayment!D59:D109,"<>No Auto",MakePayment!D59:D109,"<>") -> 30 | H7: 30 | I7: =COUNTIF(MakePayment!SE$59:SE$109,"=In Progress") -> 0 | J7: =COUNTIF(MakePayment!$D$59:$D$109,"=QA Validation") -> 30
C8: Login | D8: Android | E8: =COUNTA(Login!B7:B14) -> 8 | F8: =COUNTIFS(Login!D7:D14,"No Auto") -> 8 | G8: =COUNTIFS(Login!D7:D14,"<>No Auto",Login!D7:D14,"<>") -> 0 | H8: - | I8: =COUNTIF(Login!$D$7:SE$14,"=In Progress") -> 0 | J8: =COUNTIF(Login!$D$7:$F$14,"=QA Validation") -> 0
D9: iOS | E9: =COUNTA(Login!B16:B23) -> 8 | F9: =COUNTIFS(Login!D16:D23,"No Auto") -> 8 | G9: =COUNTIFS(Login!D16:D23,"<>No Auto",Login!D16:D23,"<>") -> 0 | H9: - | I9: =COUNTIF(Login!$D$16:$D$23,"=In Progress") -> 0 | J9: =COUNTIF(Login!$D$16:$D$23,"=QA Validation") -> 0
C10: Outages | D10: Android | E10: =COUNTA(Outages!B7:B66) -> 60 | F10: =COUNTIF(Outages!D7:D66,"No Auto") -> 0 | G10: =COUNTIFS(Outages!D7:D66,"<>No Auto",Outages!D7:D66,"<>") -> 12 | H10: 60 | I10: =COUNTIF(Outages!$D$7:$D$66,"=In Progress") -> 0 | J10: =COUNTIF(Outages!$D$7:$D$66,"=QA Validation") -> 12
D11: iOS | E11: =COUNTA(Outages!B68:B128) -> 61 | F11: =COUNTIF(Outages!D68:D128,"No Auto") -> 18 | G11: =COUNTIFS(Outages!D68:D128,"<>No Auto",Outages!D68:D128,"<>") -> 43 | H11: =COUNTIF(Outages!$D$68:$D$128,"=In Progress") -> 0 | I11: =COUNTIF(Outages!$D$68:$D$128,"=In Progress") -> 0 | J11: =COUNTIF(Outages!$D$68:$D$128,"=QA Validation") -> 43
C12: Autopay | D12: Android | E12: =COUNTA(Autopay!B7:B30) -> 24 | F12: =COUNTIF(Autopay!D7:D30,"No Auto") -> 0 | G12: =COUNTIFS(Autopay!D7:D30,"<>No Auto",Autopay!D7:D30,"<>") -> 3 | H12: 24 | I12: =COUNTIF(Autopay!$D$7:$D$30,"=In Progress") -> 0 | J12: =COUNTIF(Autopay!$D$7:$D$30,"=QA Validation") -> 3
D13: iOS | E13: =COUNTA(Autopay!B32:B55) -> 24 | F13: =COUNTIF(Autopay!D32:D55,"No Auto") -> 0 | G13: =COUNTIFS(Autopay!D32:D55,"<>No Auto",Autopay!D32:D55,"<>") -> 24 | H13: =COUNTIF(Autopay!$D$32:$D$55,"=In Progress") -> 0 | I13: =COUNTIF(Autopay!$D$32:$D$55,"=In Progress") -> 0 | J13: =COUNTIF(Autopay!$D$32:$D$55,"=QA Validation") -> 24
G14: =SUM(G4:G13) -> 149 | I14: =SUM(I4:I13) -> 0 | J14: =SUM(J4:J13) -> 149 | K14: =SUM(K4:K13) -> 0
D17: Total No Auto | E17: =SUM(F4:F13) -> 70 | I17: Total TCs | J17: =E19-E17 -> 265
D18: Total Auto | E18: =SUM(G4:G13) -> 149 | I18: TCs Automated | J18: =J14+K14 -> 149
D19: Total | E19: =SUM(E4:E13) -> 335 | I19: Overall Progress | J19: =J18/J17 -> 0.56226415
B21: Billing&Payments | D21: My Preferences | I21: My Accounts
B22: Make a Payment | D22: Push Notifications | I22: Switch Accounts
B23: Enroll in e-Bill | D23: Alert Preferences | I23: Make a Payment
B24: View Bill | D24: e-Bill enroll/de-enroll | I24: My Preferences
B25: Download Bill | D25: Autopay enroll/de-enroll | I25: My Profile
B26: Cancel Payment | D26: Budget billing enroll/de-enroll (no cmp) | I26: Web Redirect
B27: View Bill/Payment History | D27: Operations ET enroll/de-enroll | I27: Lookout
D28: Biometrics | I28: Delete My Account
D29: Cash only enroll

Sheet ManagePayments
O1: June | AS1: July
A2: Manage Payment & Wallet | E2: F | F2: SA | G2: SU | H2: M | I2: T | J2: W | K2: Th | L2: F | M2: SA | N2: SU | O2: M | P2: T | Q2: W | R2: Th | S2: F | T2: SA | U2: SU | V2: M | W2: T | X2: W | Y2: Th | Z2: F | AA2: SA | AB2: SU | AC2: M | AD2: T | AE2: W | AF2: Th | AG2: F | AH2: SA | AI2: SU | AJ2: M | AK2: T | AL2: W | AM2: Th | AN2: F | AO2: SA | AP2: SU | AQ2: M | AR2: T | AS2: W | AT2: Th | AU2: F | AV2: SA | AW2: SU | AX2: M | AY2: T | AZ2: W | BA2: Th | BB2: F | BC2: SA | BD2: SU
E3: 22 | F3: 23 | G3: 24 | H3: 25 | I3: 26 | J3: 27 | K3: 28 | L3: 29 | M3: 30 | N3: 31 | O3: 1 | P3: 2 | Q3: 3 | R3: 4 | S3: 5 | T3: 6 | U3: 7 | V3: 8 | W3: 9 | X3: 10 | Y3: 11 | Z3: 12 | AA3: 13 | AB3: 14 | AC3: 15 | AD3: 16 | AE3: 17 | AF3: 18 | AG3: 19 | AH3: 20 | AI3: 21 | AJ3: 22 | AK3: 23 | AL3: 24 | AM3: 25 | AN3: 26 | AO3: 27 | AP3: 28 | AQ3: 29 | AR3: 30 | AS3: 1 | AT3: 2 | AU3: 3 | AV3: 4 | AW3: 5 | AX3: 6 | AY3: 7 | AZ3: 8 | BA3: 9 | BB3: 10 | BC3: 11 | BD3: 12
D4: CMP - iOS / Android
A5: TC Name | B5: TC Key | C5: Assigned To | D5: Status
A6: CMP - Android
A7: CMP - MNDC-624 - Android - Delete bin icon appears after swipe right | B7: MSTREG-T22756 | C7: Kevin | D7: QA Validation
A8: CMP - MNDC-624 - Android - Perform deletion by tapping bin icon (no Kubra wallet entry) | B8: MSTREG-T22757 | C8: Kevin | D8: QA Validation
A9: CMP - MNDC-624 - Android - Backend deletion API call is triggered and succeeds | B9: MSTREG-T22758 | C9: Kevin | D9: QA Validation
A10: CMP - MNDC-624 - Android - Delete a payment hidden when eBill flag is false | B10: MSTREG-T22759 | C10: Kevin | D10: QA Validation
A11: CMP - MNDC-614 - Android - Verify "Select payment method" section is visible when eBill = 'true' | B11: MSTREG-T22760 | C11: Kevin | D11: QA Validation
A12: CMP - MNDC-614 - Android - Verify "Select payment method" section is not visible when eBill = 'false' | B12: MSTREG-T22761 | C12: Kevin | D12: QA Validation
A13: CMP - MNDC-614 - Android - CMP/SCG-group: Stored payment methods present — "Manage payment methods" redirects to Kubra and shows Payment method screen with all buttons | B13: MSTREG-T22762 | C13: Kevin | D13: QA Validation
A14: CMP - MNDC-614 - Android - CMP/SCG-group: No stored payment methods — Only "Add bank account" and "Add credit or debit card" visible; Add credit/debit opens Kubra CC/DC view | B14: MSTREG-T22763 | C14: Kevin | D14: No Auto
A15: CMP - MNDC-614 - Android - CMP/SCG-group: No Stored payment methods — Add bank account opens Kubra bank-account view | B15: MSTREG-T22764 | C15: Kevin | D15: No Auto
A16: CMP - MNDC-614 - Android - CMP/UI opcos: Stored payment methods scenario — only "Add bank account" visible; Manage and Add card not shown; Add bank redirects to Kubra bank view | B16: MSTREG-T22765 | C16: Kevin | D16: No Auto
A17: CMP - MNDC-614 - Android - UI element visibility: "Manage my wallet" button visible (independent test) | B17: MSTREG-T22766 | C17: Kevin | D17: QA Validation
A18: CMP - MNDC-258 - Android - Display Payment Methods List Populated From API | B18: MSTREG-T22767 | C18: Kevin | D18: No Auto
... A30: CMP - MNDC-1583 - Android - Checking CC's availability and display icon on changing payment methods. | B30: MSTREG-T22800 | C30: Kevin | D30: QA Validation
A31: CMP - iOS
A32: CMP - MNDC-621 - IOS - Delete bin icon appears after swipe right | B32: MSTREG-T22777 | C32: Jimmy | D32: QA Validation
A33: CMP - MNDC-621 - IOS - Perform deletion by tapping bin icon (no Kubra wallet entry) | B33: MSTREG-T22778 | C33: Jimmy | D33: QA Validation
A34: CMP - MNDC-621 - IOS - Backend deletion API call is triggered and succeeds | B34: MSTREG-T22779 | C34: Jimmy | D34: No Auto
A35: CMP - MNDC-621 - IOS - Delete a payment hidden when eBill flag is false | B35: MSTREG-T22780 | C35: Jimmy | D35: QA Validation
A36: CMP - MNDC-613 - IOS - Verify "Select payment method" section is visible when eBill = 'true' | B36: MSTREG-T22781 | C36: Jimmy | D36: QA Validation
A37: CMP - MNDC-613 - IOS - Verify "Select payment method" section is not visible when eBill = 'false' | B37: MSTREG-T22782 | C37: Jimmy | D37: QA Validation
A38: CMP - MNDC-613 - IOS - CMP/CMP-group: Stored payment methods present — "Manage payment methods" redirects to Kubra and shows Payment method screen with all buttons | B38: MSTREG-T22783 | C38: Jimmy | D38: QA Validation
A39: CMP - MNDC-613 - IOS - CMP/CMP-group: No stored payment methods — Only "Add bank account" and "Add credit or debit card" visible; Add credit/debit opens Kubra CC/DC view | B39: MSTREG-T22784 | C39: Jimmy | D39: QA Validation
A40: CMP - MNDC-613 - IOS - CMP/CMP-group: No Stored payment methods — Add bank account opens Kubra bank-account view | B40: MSTREG-T22785 | C40: Jimmy | D40: QA Validation
A41: CMP - MNDC-613 - IOS - CMP/UI opcos: Stored payment methods scenario — only "Add bank account" visible; Manage and Add card not shown; Add bank redirects to Kubra bank view | B41: MSTREG-T22786 | C41: Jimmy | D41: QA Validation
A42: CMP - MNDC-613 - IOS - UI element visibility: "Manage my wallet" button visible (independent test) | B42: MSTREG-T22787 | C42: Jimmy | D42: QA Validation
A43: CMP - MNDC-390 - IOS - Display Payment Methods List Populated From API | B43: MSTREG-T22788 | C43: Jimmy | D43: No Auto
... A55: CMP - MNDC-1583 - iOS - Checking CC's availability and display icon on changing payment methods. | B55: MSTREG-T22803 | C55: Jimmy | D55: QA Validation

Sheet MakePayment
O1: June | AS1: July
A2: Make a Payment Flow | E2: F | F2: SA | G2: SU | H2: M | I2: T | J2: W | K2: Th | L2: F | M2: SA | N2: SU | O2: M | P2: T | Q2: W | R2: Th | S2: F | T2: SA | U2: SU | V2: M | W2: T | X2: W | Y2: Th | Z2: F | AA2: SA | AB2: SU | AC2: M | AD2: T | AE2: W | AF2: Th | AG2: F | AH2: SA | AI2: SU | AJ2: M | AK2: T | AL2: W | AM2: Th | AN2: F | AO2: SA | AP2: SU | AQ2: M | AR2: T | AS2: W | AT2: Th | AU2: F | AV2: SA | AW2: SU | AX2: M | AY2: T | AZ2: W | BA2: Th | BB2: F | BC2: SA | BD2: SU
E3: 22 | F3: 23 | G3: 24 | H3: 25 | I3: 26 | J3: 27 | K3: 28 | L3: 29 | M3: 30 | N3: 31 | O3: 1 | P3: 2 | Q3: 3 | R3: 4 | S3: 5 | T3: 6 | U3: 7 | V3: 8 | W3: 9 | X3: 10 | Y3: 11 | Z3: 12 | AA3: 13 | AB3: 14 | AC3: 15 | AD3: 16 | AE3: 17 | AF3: 18 | AG3: 19 | AH3: 20 | AI3: 21 | AJ3: 22 | AK3: 23 | AL3: 24 | AM3: 25 | AN3: 26 | AO3: 27 | AP3: 28 | AQ3: 29 | AR3: 30 | AS3: 1 | AT3: 2 | AU3: 3 | AV3: 4 | AW3: 5 | AX3: 6 | AY3: 7 | AZ3: 8 | BA3: 9 | BB3: 10 | BC3: 11 | BD3: 12
D4: CMP - iOS / Android
A5: TC Name | B5: TC Key | C5: Assigned To | D5: Status
A6: CMP - Android
A7: MNDC-1837 - CMP - Android - Access Make a payment from Bills & Payments for eBill account | B7: MSTREG-T22473
A8: MNDC-1837 - CMP - Android - Access Make a payment from Home widget for eBill account | B8: MSTREG-T22474
A9: MNDC-1837 - CMP - Android - Access Make a payment from Account > Make a payment | B9: MSTREG-T22475
A10: MNDC-1837 - CMP - Android - Make a payment flow visible only when eBill = true | B10: MSTREG-T22476
A11: MNDC-1837 - CMP - Android - At least one payment method saved – list and selection | B11: MSTREG-T22477
A12: MNDC-1837 - CMP - Android - Payment amount defaulted to Amount due in normal billing period | B12: MSTREG-T22478
A13: MNDC-1837 - CMP - Android - Payment amount shows total balance for payment plan or budget billing | B13: MSTREG-T22479
A14: MNDC-1837 - CMP - Android - Payment amount not editable for Past Due accounts | B14: MSTREG-T22480
A15: MNDC-1837 - CMP - Android - Payment amount not editable for Final Termination Notice accounts | B15: MSTREG-T22481
A16: MNDC-1837 - CMP - Android - Payment date defaults to Today and editable for normal billing | B16: MSTREG-T22482
A17: MNDC-1837 - CMP - Android - Payment date not schedulable for Past Due accounts | B17: MSTREG-T22483
A18: MNDC-1837 - CMP - Android - Payment date not schedulable for Final Termination Notice accounts | B18: MSTREG-T22484
... A49: CMP - MNDC-1837 - Android - Cash nonRes | B49: MSTREG-T22515
A50: CMP - MNDC-279 - Android - Non eBill - New ACH Payment with Bank Account Selected | B50: MSTREG-T22567 | D50: No Auto
A51: CMP - MNDC-279 - Android - Non eBill - Existing ACH Payment (Remember Me) - Display Stored Payment Methods | B51: MSTREG-T22568
A52: CMP - MNDC-279 - Android - Non eBill - New Credit/Debit Card Payment | B52: MSTREG-T22569 | D52: No Auto
A53: CMP - MNDC-279 - Android - Non eBill - Existing Credit/Debit Card Payment - Display Stored Payment Methods | B53: MSTREG-T22570
A54: CMP - MNDC-279 - Android - eBill - Payemnt with New ACH Payment with Bank Account Selected | B54: MSTREG-T22571 | D54: No Auto
A55: CMP - MNDC-279 - Android - eBill - Payment with existing ACH Payment | B55: MSTREG-T22572
A56: CMP - MNDC-279 - Android - eBill - Payment with ew Credit/Debit Card Payment | B56: MSTREG-T22573 | D56: No Auto
A57: CMP - MNDC-279 - Android - eBill - Payment with existing Credit/Debit Card Payment | B57: MSTREG-T22574
A58: CMP - iOS
A59: MNDC-1834 - CMP - IOS - Access Make a payment from Bills & Payments for eBill account | B59: MSTREG-T22516 | C59: Nicolas | D59: QA Validation
A60: MNDC-1834 - CMP - IOS - Access Make a payment from Home widget for eBill account | B60: MSTREG-T22517 | C60: Nicolas | D60: QA Validation
A61: MNDC-1834 - CMP - IOS - Access Make a payment from Account > Make a payment | B61: MSTREG-T22518 | C61: Nicolas | D61: QA Validation
A62: MNDC-1834 - CMP - IOS - Make a payment flow visible only when eBill = true | B62: MSTREG-T22519 | C62: Nicolas | D62: QA Validation
A63: MNDC-1834 - CMP - IOS - At least one payment method saved – list and selection | B63: MSTREG-T22520 | C63: Nicolas | D63: QA Validation
A64: MNDC-1834 - CMP - IOS - Payment amount defaulted to Amount due in normal billing period | B64: MSTREG-T22521 | C64: Nicolas | D64: QA Validation
A65: MNDC-1834 - CMP - IOS - Payment amount shows total balance for payment plan or budget billing | B65: MSTREG-T22522 | C65: Nicolas | D65: QA Validation
A66: MNDC-1834 - CMP - IOS - Payment amount not editable for Past Due accounts | B66: MSTREG-T22523 | C66: Nicolas | D66: No Auto
A67: MNDC-1834 - CMP - IOS - Payment amount not editable for Final Termination Notice accounts | B67: MSTREG-T22524 | C67: Nicolas | D67: No Auto
A68: MNDC-1834 - CMP - IOS - Payment date defaults to Today and editable for normal billing | B68: MSTREG-T22525 | C68: Nicolas | D68: No Auto
A69: MNDC-1834 - CMP - IOS - Payment date not schedulable for Past Due accounts | B69: MSTREG-T22526 | C69: Nicolas | D69: QA Validation
A70: MNDC-1834 - CMP - IOS - Payment date not schedulable for Final Termination Notice accounts | B70: MSTREG-T22527 | C70: Nicolas | D70: No Auto
...

Sheet Login
O1: June | AS1: July
A2: Login | E2: F | F2: SA | G2: SU | H2: M | I2: T | J2: W | K2: Th | L2: F | M2: SA | N2: SU | O2: M | P2: T | Q2: W | R2: Th | S2: F | T2: SA | U2: SU | V2: M | W2: T | X2: W | Y2: Th | Z2: F | AA2: SA | AB2: SU | AC2: M | AD2: T | AE2: W | AF2: Th | AG2: F | AH2: SA | AI2: SU | AJ2: M | AK2: T | AL2: W | AM2: Th | AN2: F | AO2: SA | AP2: SU | AQ2: M | AR2: T | AS2: W | AT2: Th | AU2: F | AV2: SA | AW2: SU | AX2: M | AY2: T | AZ2: W | BA2: Th | BB2: F | BC2: SA | BD2: SU
E3: 22 | F3: 23 | G3: 24 | H3: 25 | I3: 26 | J3: 27 | K3: 28 | L3: 29 | M3: 30 | N3: 31 | O3: 1 | P3: 2 | Q3: 3 | R3: 4 | S3: 5 | T3: 6 | U3: 7 | V3: 8 | W3: 9 | X3: 10 | Y3: 11 | Z3: 12 | AA3: 13 | AB3: 14 | AC3: 15 | AD3: 16 | AE3: 17 | AF3: 18 | AG3: 19 | AH3: 20 | AI3: 21 | AJ3: 22 | AK3: 23 | AL3: 24 | AM3: 25 | AN3: 26 | AO3: 27 | AP3: 28 | AQ3: 29 | AR3: 30 | AS3: 1 | AT3: 2 | AU3: 3 | AV3: 4 | AW3: 5 | AX3: 6 | AY3: 7 | AZ3: 8 | BA3: 9 | BB3: 10 | BC3: 11 | BD3: 12
D4: CMP - iOS / Android
A5: TC Name | B5: TC Key | C5: Assigned To | D5: Status
A6: CMP - Android
A7: CMP - IOS - First-Time Login - Enable Biometric Setup (Happy Path) | B7: MSTREG-T22743 | D7: No Auto
A8: CMP - IOS - First-Time Login - Decline / Cancel Biometric Setup | B8: MSTREG-T22744 | D8: No Auto
A9: CMP - IOS - Returning User - Successful Biometric Login (Cold Start & Auto-Prompt) | B9: MSTREG-T22745 | D9: No Auto
A10: CMP - IOS - Biometric Failure - Retry - Repeated Failure - Manual Fallback | B10: MSTREG-T22746 | D10: No Auto
A11: CMP - IOS - Biometric Not Available - Device and System Level Issues | B11: MSTREG-T22747 | D11: No Auto
A12: CMP - IOS - Biometric Edge Cases - Timeout, Multi-User, Cancel Prompt, Warm Start | B12: MSTREG-T22748 | D12: No Auto
A13: CMP - IOS - Session Timeout - Notification and Biometric Re-authentication | B13: MSTREG-T22749 | D13: No Auto
A14: CMP - IOS - Ionic to Native App Upgrade - Biometric Continuity | B14: MSTREG-T22750 | D14: No Auto
A15: CMP - iOS
A16: CMP - IOS - First-Time Login - Enable Biometric Setup (Happy Path) | B16: MSTREG-T22743 | D16: No Auto
A17: CMP - IOS - First-Time Login - Decline / Cancel Biometric Setup | B17: MSTREG-T22744 | D17: No Auto
A18: CMP - IOS - Returning User - Successful Biometric Login (Cold Start & Auto-Prompt) | B18: MSTREG-T22745 | D18: No Auto
A19: CMP - IOS - Biometric Failure - Retry - Repeated Failure - Manual Fallback | B19: MSTREG-T22746 | D19: No Auto
A20: CMP - IOS - Biometric Not Available - Device and System Level Issues | B20: MSTREG-T22747 | D20: No Auto
A21: CMP - IOS - Biometric Edge Cases - Timeout, Multi-User, Cancel Prompt, Warm Start | B21: MSTREG-T22748 | D21: No Auto
A22: CMP - IOS - Session Timeout - Notification and Biometric Re-authentication | B22: MSTREG-T22749 | D22: No Auto
A23: CMP - IOS - Ionic to Native App Upgrade - Biometric Continuity | B23: MSTREG-T22750 | D23: No Auto

Sheet Autopay
O1: June | AS1: July | BE1: July
A2: Autopay | E2: F | F2: SA | G2: SU | H2: M | I2: T | J2: W | K2: Th | L2: F | M2: SA | N2: SU | O2: M | P2: T | Q2: W | R2: Th | S2: F | T2: SA | U2: SU | V2: M | W2: T | X2: W | Y2: Th | Z2: F | AA2: SA | AB2: SU | AC2: M | AD2: T | AE2: W | AF2: Th | AG2: F | AH2: SA | AI2: SU | AJ2: M | AK2: T | AL2: W | AM2: Th | AN2: F | AO2: SA | AP2: SU | AQ2: M | AR2: T | AS2: W | AT2: Th | AU2: F | AV2: SA | AW2: SU | AX2: M | AY2: T | AZ2: W | BA2: Th | BB2: F | BC2: SA | BD2: SU | BE2: M | BF2: T | BG2: W | BH2: Th | BI2: F | BJ2: SA | BK2: SU
E3: 22 | F3: 23 | G3: 24 | H3: 25 | I3: 26 | J3: 27 | K3: 28 | L3: 29 | M3: 30 | N3: 31 | O3: 1 | P3: 2 | Q3: 3 | R3: 4 | S3: 5 | T3: 6 | U3: 7 | V3: 8 | W3: 9 | X3: 10 | Y3: 11 | Z3: 12 | AA3: 13 | AB3: 14 | AC3: 15 | AD3: 16 | AE3: 17 | AF3: 18 | AG3: 19 | AH3: 20 | AI3: 21 | AJ3: 22 | AK3: 23 | AL3: 24 | AM3: 25 | AN3: 26 | AO3: 27 | AP3: 28 | AQ3: 29 | AR3: 30 | AS3: 1 | AT3: 2 | AU3: 3 | AV3: 4 | AW3: 5 | AX3: 6 | AY3: 7 | AZ3: 8 | BA3: 9 | BB3: 10 | BC3: 11 | BD3: 12 | BE3: 13 | BF3: 14 | BG3: 15 | BH3: 16 | BI3: 17 | BJ3: 18 | BK3: 19
D4: CMP - iOS / Android
A5: TC Name | B5: TC Key | C5: Assigned To | D5: Status
A6: CMP - Android
A7: MNDC-2174 - CMP - Android - Feature is visible only when Account is CMP and eBill = true and Autopay = false | B7: MSTREG-T22575 | C7: Jimmy | D7: QA Validation
A8: MNDC-2174 - CMP - Android - Feature hidden when eBill=false even if CMP=true | B8: MSTREG-T22576 | C8: Jimmy | D8: QA Validation
A9: MNDC-2174 - CMP - Android - Attempt to add Credit Card is blocked for CMP eBill user | B9: MSTREG-T22577 | C9: Jimmy | D9: QA Validation
A10: MNDC-2174 - CMP - Android - Empty state when no payment method exists | B10: MSTREG-T22578 | C10: Jimmy
A11: MNDC-2174 - CMP - Android - Existing bank account is displayed when present | B11: MSTREG-T22579 | C11: Jimmy
A12: MNDC-2174 - CMP - Android - Schedule AutoPay label and helper text are present | B12: MSTREG-T22580 | C12: Jimmy
A13: MNDC-2174 - CMP - Android - Schedule dropdown default value = 10 | B13: MSTREG-T22581 | C13: Jimmy
A14: MNDC-2174 - CMP - Android - Schedule dropdown allowed range 5–23 inclusive | B14: MSTREG-T22582 | C14: Jimmy
A15: MNDC-2174 - CMP - Android - Payment Amount minimum = $1.00 with error below minimum | B15: MSTREG-T22583 | C15: Jimmy
A16: MNDC-2174 - CMP - Android - Payment Amount maximum = $99,999.99 with error above maximum | B16: MSTREG-T22584 | C16: Jimmy
A17: MNDC-2174 - CMP - Android - Payment Amount accepts boundary values $1.00 and $99,999.99 | B17: MSTREG-T22585 | C17: Jimmy
A18: MNDC-2174 - CMP - Android - Payment Amount rejects non-numeric and too many decimals | B18: MSTREG-T22586 | C18: Jimmy
A19: MNDC-2174 - CMP - Android - Successful enrollment with existing bank account | B19: MSTREG-T22587 | C19: Jimmy
A20: MNDC-2174 - CMP - Android - Successful enrollment by adding a new bank account during flow | B20: MSTREG-T22588 | C20: Jimmy
A21: MNDC-2174 - CMP - Android - Attempt to enroll without selecting/adding a bank account | B21: MSTREG-T22589 | C21: Jimmy
... A30: MNDC-2174 - CMP - Android - Confirmation screen appears after successful validation and enrollment | B30: MSTREG-T22598 | C30: Jimmy
A31: CMP - iOS
A32: MNDC-2173 - CMP - IOS - Feature is visible only when Account is CMP and eBill = true and Autopay = false | B32: MSTREG-T22599 | C32: Jimmy | D32: QA Validation
A33: MNDC-2173 - CMP - IOS - Feature hidden when eBill=false even if CMP=true | B33: MSTREG-T22600 | C33: Jimmy | D33: QA Validation
A34: MNDC-2173 - CMP - IOS - Attempt to add Credit Card is blocked for CMP eBill user | B34: MSTREG-T22601 | C34: Jimmy | D34: QA Validation
A35: MNDC-2173 - CMP - IOS - Empty state when no payment method exists | B35: MSTREG-T22602 | C35: Jimmy | D35: QA Validation
A36: MNDC-2173 - CMP - IOS - Existing bank account is displayed when present | B36: MSTREG-T22603 | C36: Jimmy | D36: QA Validation
A37: MNDC-2173 - CMP - IOS - Schedule AutoPay label and helper text are present | B37: MSTREG-T22604 | C37: Jimmy | D37: QA Validation
A38: MNDC-2173 - CMP - IOS - Schedule dropdown default value = 10 | B38: MSTREG-T22605 | C38: Jimmy | D38: QA Validation
A39: MNDC-2173 - CMP - IOS - Schedule dropdown allowed range 5–23 inclusive | B39: MSTREG-T22606 | C39: Jimmy | D39: QA Validation
A40: MNDC-2173 - CMP - IOS - Payment Amount minimum = $1.00 with error below minimum | B40: MSTREG-T22607 | C40: Jimmy | D40: QA Validation
A41: MNDC-2173 - CMP - IOS - Payment Amount maximum = $99,999.99 with error above maximum | B41: MSTREG-T22608 | C41: Jimmy | D41: QA Validation
A42: MNDC-2173 - CMP - IOS - Payment Amount accepts boundary values $1.00 and $99,999.99 | B42: MSTREG-T22609 | C42: Jimmy | D42: QA Validation
A43: MNDC-2173 - CMP - IOS - Payment Amount rejects non-numeric and too many decimals | B43: MSTREG-T22610 | C43: Jimmy | D43: QA Validation
... A55: End Autopay | B55: EXTRA | C55: Jimmy | D55: QA Validation

Sheet Outages
O1: June | AS1: July
A2: Outages | E2: F | F2: SA | G2: SU | H2: M | I2: T | J2: W | K2: Th | L2: F | M2: SA | N2: SU | O2: M | P2: T | Q2: W | R2: Th | S2: F | T2: SA | U2: SU | V2: M | W2: T | X2: W | Y2: Th | Z2: F | AA2: SA | AB2: SU | AC2: M | AD2: T | AE2: W | AF2: Th | AG2: F | AH2: SA | AI2: SU | AJ2: M | AK2: T | AL2: W | AM2: Th | AN2: F | AO2: SA | AP2: SU | AQ2: M | AR2: T | AS2: W | AT2: Th | AU2: F | AV2: SA | AW2: SU | AX2: M | AY2: T | AZ2: W | BA2: Th | BB2: F | BC2: SA | BD2: SU | BE2: M | BF2: T | BG2: W | BH2: Th | BI2: F | BJ2: SA | BK2: SU | BL2: M | BM2: T | BN2: W | BO2: Th | BP2: F | BQ2: SA | BR2: SU | BS2: M | BT2: T | BU2: W | BV2: Th | BW2: F | BX2: SA | BY2: SU
E3: 22 | F3: 23 | G3: 24 | H3: 25 | I3: 26 | J3: 27 | K3: 28 | L3: 29 | M3: 30 | N3: 31 | O3: 1 | P3: 2 | Q3: 3 | R3: 4 | S3: 5 | T3: 6 | U3: 7 | V3: 8 | W3: 9 | X3: 10 | Y3: 11 | Z3: 12 | AA3: 13 | AB3: 14 | AC3: 15 | AD3: 16 | AE3: 17 | AF3: 18 | AG3: 19 | AH3: 20 | AI3: 21 | AJ3: 22 | AK3: 23 | AL3: 24 | AM3: 25 | AN3: 26 | AO3: 27 | AP3: 28 | AQ3: 29 | AR3: 30 | AS3: 1 | AT3: 2 | AU3: 3 | AV3: 4 | AW3: 5 | AX3: 6 | AY3: 7 | AZ3: 8 | BA3: 9 | BB3: 10 | BC3: 11 | BD3: 12 | BE3: 13 | BF3: 14 | BG3: 15 | BH3: 16 | BI3: 17 | BJ3: 18 | BK3: 19 | BL3: 20 | BM3: 21 | BN3: 22 | BO3: 23 | BP3: 24 | BQ3: 25 | BR3: 26 | BS3: 27 | BT3: 28 | BU3: 29 | BV3: 30 | BW3: 31 | BX3: 32 | BY3: 33
D4: CMP - iOS / Android
A5: TC Name | B5: TC Key | C5: Assigned To | D5: Status
A6: CMP - Android
A7: CMP - MNDC-111 - Android - Outage List opens in in-app web with SSO (CMP) | B7: MSTREG-T22622 | C7: Nicolas | D7: QA Validation
A8: CMP - MNDC-111 - Android - Outage Map opens in in-app web (CMP) | B8: MSTREG-T22623 | C8: Nicolas | D8: QA Validation
A9: CMP - MNDC-111 - Android - Outage Central redirects to CMP outages landing with SSO | B9: MSTREG-T22624 | C9: Nicolas | D9: QA Validation
A10: CMP - MNDC-111 - Android - Facebook opens native app for CMP if installed | B10: MSTREG-T22625 | C10: Nicolas | D10: QA Validation
